<?xml version="1.0"?>
<robot name="kyun" xmlns:xacro="http://www.ros.org/wiki/xacro">

<material name="gray">
  <color rgba="0.5 0.5 0.5 2.5"/>
</material>
<material name="white">
  <color rgba="1.0 1.0 1.0 1"/>
</material>

<link name="world"/>
<joint name="world_to_base" type="fixed">
  <origin xyz="0 0 0.0465"/>
  <parent link="world"/>
  <child link="base_link"/>
</joint>

<link name="base_link">
  <visual>
    <geometry>
      <mesh filename="package://kyun_description/mesh/servo01.stl" scale="0.001 0.001 0.001"/>
      <origin xyz="0 0 0.0465"/>
    </geometry>
    <material name="gray"/>
  </visual>
  <collision>
    <geometry>
      <mesh filename="package://kyun_description/mesh/servo01.stl" scale="0.0009 0.0009 0.0009"/>
      <origin xyz="0 0 0.0465"/>
    </geometry>
  </collision>
  <inertial>
    <mass value="0.0572"/>
    <inertia ixx="0.00093819916" ixy="0" ixz="0" iyy="0.00158169916" iyz="0" izz="0.001417845"/>
  </inertial>
</link>

<gazebo reference="base_link">
  <material>Gazebo/Grey</material>
</gazebo>

<joint name="base_to_second" type="revolute">
  <parent link="base_link"/>
  <child link="second_link"/>
  <origin xyz="0 0 0" rpy="0 0 0"/>
  <axis xyz="0 0 1"/>
  <dynamics damping="0.7"/>
  <limit lower="-1.5" upper="1.5" effort="0.5" velocity="6.0"/>
</joint>

<transmission name="base_trans">
    <type>transmission_interface/SimpleTransmission</type>
    <joint name="base_to_second">
      <hardwareInterface>hardware_interface/PositionJointInterface</hardwareInterface>
    </joint>
    <actuator name="base_motor">
      <hardwareInterface>hardware_interface/PositionJointInterface</hardwareInterface>
      <mechanismReduction>1</mechanismReduction>
    </actuator>
</transmission>

<link name="second_link">
  <visual>
    <geometry>
      <mesh filename="package://kyun_description/mesh/frame12.stl" scale="0.001 0.001 0.001"/>
      <origin xyz="0 0 0"/>
    </geometry>
    <material name="grey"/>
  </visual>
  <collision>
    <geometry>
      <mesh filename="package://kyun_description/mesh/frame12.stl" scale="0.0009 0.0009 0.0009"/>
      <origin xyz="0 0 0"/>
    </geometry>
  </collision>
  <inertial>
    <mass value="0.0228"/>
    <inertia ixx="0.0012587" ixy="0" ixz="0" iyy="0.0009052" iyz="0" izz="0.0010677"/>
  </inertial>
</link>

<gazebo reference="second_link">
  <material>Gazebo/Grey</material>
</gazebo>

<joint name="second_to_third" type="revolute">
  <parent link="second_link"/>
  <child link="third_link"/>
  <origin xyz="-0.00963 0.019 0.05" rpy="0 0 0"/>
  <axis xyz="0 1 0"/>
  <dynamics damping="0.7"/>
  <limit lower="-1.5" upper="1.5" effort="0.5" velocity="6.0"/>
</joint>

<transmission name="second_trans">
    <type>transmission_interface/SimpleTransmission</type>
    <joint name="second_to_third">
      <hardwareInterface>hardware_interface/PositionJointInterface</hardwareInterface>
    </joint>
    <actuator name="second_motor">
      <hardwareInterface>hardware_interface/PositionJointInterface</hardwareInterface>
      <mechanismReduction>1</mechanismReduction>
    </actuator>
</transmission>

<link name="third_link">
  <visual>
    <geometry>
      <mesh filename="package://kyun_description/mesh/servo02.stl" scale="0.001 0.001 0.001"/>
      <origin xyz="0 0 0"/>
    </geometry>
    <material name="grey"/>
  </visual>
  <collision>
    <geometry>
      <mesh filename="package://kyun_description/mesh/servo02.stl" scale="0.0009 0.0009 0.0009"/>
      <origin xyz="0 0 0"/>
    </geometry>
  </collision>
  <inertial>
    <mass value="0.0638"/>
    <inertia ixx="0.0021267" ixy="0" ixz="0" iyy="0.0020277" iyz="0" izz="0.0011317"/>
  </inertial>
</link>

<gazebo reference="third_link">
  <material>Gazebo/Grey</material>
</gazebo>

<joint name="third_to_fourth" type="revolute">
  <parent link="third_link"/>
  <child link="fourth_link"/>
  <origin xyz="0.019 -0.018 0.06075" rpy="0 0 0"/>
  <axis xyz="1 0 0"/>
  <dynamics damping="0.7"/>
  <limit lower="-1.5" upper="1.5" effort="0.5" velocity="6.0"/>
</joint>

<transmission name="third_trans">
    <type>transmission_interface/SimpleTransmission</type>
    <joint name="third_to_fourth">
      <hardwareInterface>hardware_interface/PositionJointInterface</hardwareInterface>
    </joint>
    <actuator name="third_motor">
      <hardwareInterface>hardware_interface/PositionJointInterface</hardwareInterface>
      <mechanismReduction>1</mechanismReduction>
    </actuator>
</transmission>

<link name="fourth_link">
  <visual>
    <geometry>
      <mesh filename="package://kyun_description/mesh/servo03.stl" scale="0.001 0.001 0.001"/>
    </geometry>
    <material name="grey"/>
  </visual>
  <collision>
    <geometry>
      <mesh filename="package://kyun_description/mesh/servo03.stl" scale="0.0009 0.0009 0.0009"/>
    </geometry>
  </collision>
  <inertial>
    <mass value="0.099806"/>
    <inertia ixx="0.0028791" ixy="0" ixz="0" iyy="0.0028648" iyz="0" izz="0.0021805"/>
  </inertial>
</link>

<gazebo reference="fourth_link">
  <material>Gazebo/Grey</material>
</gazebo>

<joint name="fourth_to_fifth" type="revolute">
  <parent link="fourth_link"/>
  <child link="fifth_link"/>
  <origin xyz="-0.019 -0.02 0.024" rpy="0 0 0"/>
  <axis xyz="0 1 0"/>
  <dynamics damping="0.7"/>
  <limit lower="-1.5" upper="1.5" effort="0.5" velocity="6.0"/>
</joint>

<transmission name="fourth_trans">
    <type>transmission_interface/SimpleTransmission</type>
    <joint name="fourth_to_fifth">
      <hardwareInterface>hardware_interface/PositionJointInterface</hardwareInterface>
    </joint>
    <actuator name="fourth_motor">
      <hardwareInterface>hardware_interface/PositionJointInterface</hardwareInterface>
      <mechanismReduction>1</mechanismReduction>
    </actuator>
</transmission>

<link name="fifth_link">
  <visual>
    <geometry>
      <mesh filename="package://kyun_description/mesh/servo04.stl" scale="0.001 0.001 0.001"/>
    </geometry>
    <material name="grey"/>
  </visual>
  <collision>
    <geometry>
      <mesh filename="package://kyun_description/mesh/servo04.stl" scale="0.0009 0.0009 0.0009"/>
    </geometry>
  </collision>
  <inertial>
    <mass value="0.063759"/>
    <inertia ixx="0.0020277" ixy="0" ixz="0" iyy="0.0021267" iyz="0" izz="0.0011317"/>
  </inertial>
</link>

<gazebo reference="fifth_link">
  <material>Gazebo/Grey</material>
</gazebo>

<joint name="fifth_to_sixth" type="revolute">
  <parent link="fifth_link"/>
  <child link="sixth_link"/>
  <origin xyz="0.0205 0.02 0.06075" rpy="0 0 0"/>
  <axis xyz="1 0 0"/>
  <dynamics damping="0.7"/>
  <limit lower="-1.5" upper="1.5" effort="0.5" velocity="6.0"/>
</joint>

<transmission name="fifth_trans">
    <type>transmission_interface/SimpleTransmission</type>
    <joint name="fifth_to_sixth">
      <hardwareInterface>hardware_interface/PositionJointInterface</hardwareInterface>
    </joint>
    <actuator name="fifth_motor">
      <hardwareInterface>hardware_interface/EPositionJointInterface</hardwareInterface>
       <mechanismReduction>1</mechanismReduction>
    </actuator>
</transmission>

<link name="sixth_link">
  <visual>
    <geometry>
      <mesh filename="package://kyun_description/mesh/frame13.stl" scale="0.001 0.001 0.001"/>
    </geometry>
    <material name="white"/>
  </visual>
  <collision>
    <geometry>
      <mesh filename="package://kyun_description/mesh/frame13.stl" scale="0.0009 0.0009 0.0009"/>
    </geometry>
  </collision>
  <inertial>
    <mass value="0.059571"/>
    <inertia ixx="0.0011416" ixy="0" ixz="0" iyy="0.0011103" iyz="0" izz="0.0020421"/>
  </inertial>
</link>

<gazebo reference="sixth_link">
  <material>Gazebo/white</material>
</gazebo>

<gazebo>
  <plugin name="gazebo_ros_control" filename="libgazebo_ros_control.so">
    <robotNamespace>/kyun</robotNamespace>
    <robotSimType>gazebo_ros_control/DefaultRobotHWSim</robotSimType>
    <legacyModeNS>true</legacyModeNS>
  </plugin>
  <plugin name="joint_state_publisher" filename="libgazebo_ros_joint_state_publisher.so">
    <jointName>base_to_second, second_to_third, third_to_fourth, fourth_to_fifth, fifth_to_sixth</jointName>
  </plugin>
</gazebo>

</robot>
